Workbook

Sheet Set Counts
A1: Card Counts by Set
B2: Upgrades | C2: Quests | D2: Death Curses | E2: Stone Cards | F2: Heroes | G2: Monsters | H2: Pets | I2: Mounts | J2: Dragons | K2: Dragon Turns
A3: Arcadia Quest | B3: =SUMIF(Upgrades[],'Set Counts'!$A3,Upgrades[QTY]) -> 161 | C3: =COUNTIF(Quests[Set],'Set Counts'!$A3) -> 23 | D3: =SUMIF(DeathCurses[],'Set Counts'!$A3,DeathCurses[Qty]) -> 24 | E3: =SUMIF(StoneCards[],'Set Counts'!$A3,StoneCards[Qty]) -> 0 | F3: =COUNTIF(Heroes[Set],'Set Counts'!$A3) -> 12 | G3: =COUNTIF(Monsters[Set],'Set Counts'!$A3) -> 42 | H3: =COUNTIF(Pets[Set],'Set Counts'!$A3) -> 0 | I3: =COUNTIF(Mounts[Set],'Set Counts'!$A3) -> 0 | J3: 0 | K3: =SUMIF(DragonTurns[],'Set Counts'!$A3,DragonTurns[Qty]) -> 0
A4: Beyond the Grave | B4: =SUMIF(Upgrades[],'Set Counts'!$A4,Upgrades[QTY]) -> 48 | C4: =COUNTIF(Quests[Set],'Set Counts'!A4) -> 14 | D4: =SUMIF(DeathCurses[],'Set Counts'!$A4,DeathCurses[Qty]) -> 0 | E4: =SUMIF(StoneCards[],'Set Counts'!$A4,StoneCards[Qty]) -> 14 | F4: =COUNTIF(Heroes[Set],'Set Counts'!$A4) -> 2 | G4: =COUNTIF(Monsters[Set],'Set Counts'!$A4) -> 36 | H4: =COUNTIF(Pets[Set],'Set Counts'!$A4) -> 0 | I4: =COUNTIF(Mounts[Set],'Set Counts'!$A4) -> 0 | J4: 0 | K4: =SUMIF(DragonTurns[],'Set Counts'!$A4,DragonTurns[Qty]) -> 0
A5: Inferno | B5: =SUMIF(Upgrades[],'Set Counts'!$A5,Upgrades[QTY]) -> 152 | C5: =COUNTIF(Quests[Set],'Set Counts'!A5) -> 21 | D5: =SUMIF(DeathCurses[],'Set Counts'!$A5,DeathCurses[Qty]) -> 24 | E5: =SUMIF(StoneCards[],'Set Counts'!$A5,StoneCards[Qty]) -> 14 | F5: =COUNTIF(Heroes[Set],'Set Counts'!$A5) -> 17 | G5: =COUNTIF(Monsters[Set],'Set Counts'!$A5) -> 48 | H5: =COUNTIF(Pets[Set],'Set Counts'!$A5) -> 0 | I5: =COUNTIF(Mounts[Set],'Set Counts'!$A5) -> 0 | J5: 0 | K5: =SUMIF(DragonTurns[],'Set Counts'!$A5,DragonTurns[Qty]) -> 0
A6: Pets | B6: =SUMIF(Upgrades[],'Set Counts'!$A6,Upgrades[QTY]) -> 20 | C6: =COUNTIF(Quests[Set],'Set Counts'!A6) -> 10 | D6: =SUMIF(DeathCurses[],'Set Counts'!$A6,DeathCurses[Qty]) -> 0 | E6: =SUMIF(StoneCards[],'Set Counts'!$A6,StoneCards[Qty]) -> 0 | F6: =COUNTIF(Heroes[Set],'Set Counts'!$A6) -> 2 | G6: =COUNTIF(Monsters[Set],'Set Counts'!$A6) -> 20 | H6: =COUNTIF(Pets[Set],'Set Counts'!$A6) -> 36 | I6: =COUNTIF(Mounts[Set],'Set Counts'!$A6) -> 0 | J6: 0 | K6: =SUMIF(DragonTurns[],'Set Counts'!$A6,DragonTurns[Qty]) -> 0
A7: Riders | B7: =SUMIF(Upgrades[],'Set Counts'!$A7,Upgrades[QTY]) -> 47 | C7: =COUNTIF(Quests[Set],'Set Counts'!A7) -> 15 | D7: =SUMIF(DeathCurses[],'Set Counts'!$A7,DeathCurses[Qty]) -> 0 | E7: =SUMIF(StoneCards[],'Set Counts'!$A7,StoneCards[Qty]) -> 0 | F7: =COUNTIF(Heroes[Set],'Set Counts'!$A7) -> 2 | G7: =COUNTIF(Monsters[Set],'Set Counts'!$A7) -> 8 | H7: =COUNTIF(Pets[Set],'Set Counts'!$A7) -> 0 | I7: =COUNTIF(Mounts[Set],'Set Counts'!$A7) -> 6 | J7: 0 | K7: =SUMIF(DragonTurns[],'Set Counts'!$A7,DragonTurns[Qty]) -> 0
A8: Chaos Dragon | B8: =SUMIF(Upgrades[],'Set Counts'!$A8,Upgrades[QTY]) -> 27 | C8: =COUNTIF(Quests[Set],'Set Counts'!A8) -> 1 | D8: =SUMIF(DeathCurses[],'Set Counts'!$A8,DeathCurses[Qty]) -> 0 | E8: =SUMIF(StoneCards[],'Set Counts'!$A8,StoneCards[Qty]) -> 14 | F8: =COUNTIF(Heroes[Set],'Set Counts'!$A8) -> 0 | G8: =COUNTIF(Monsters[Set],'Set Counts'!$A8) -> 0 | H8: =COUNTIF(Pets[Set],'Set Counts'!$A8) -> 0 | I8: =COUNTIF(Mounts[Set],'Set Counts'!$A8) -> 0 | J8: 2 | K8: =SUMIF(DragonTurns[],'Set Counts'!$A8,DragonTurns[Qty]) -> 24
A9: Fire Dragon | B9: =SUMIF(Upgrades[],'Set Counts'!$A9,Upgrades[QTY]) -> 27 | C9: =COUNTIF(Quests[Set],'Set Counts'!A9) -> 1 | D9: =SUMIF(DeathCurses[],'Set Counts'!$A9,DeathCurses[Qty]) -> 0 | E9: =SUMIF(StoneCards[],'Set Counts'!$A9,StoneCards[Qty]) -> 14 | F9: =COUNTIF(Heroes[Set],'Set Counts'!$A9) -> 0 | G9: =COUNTIF(Monsters[Set],'Set Counts'!$A9) -> 0 | H9: =COUNTIF(Pets[Set],'Set Counts'!$A9) -> 0 | I9: =COUNTIF(Mounts[Set],'Set Counts'!$A9) -> 0 | J9: 2 | K9: =SUMIF(DragonTurns[],'Set Counts'!$A9,DragonTurns[Qty]) -> 24
A10: Frost Dragon | B10: =SUMIF(Upgrades[],'Set Counts'!$A10,Upgrades[QTY]) -> 27 | C10: =COUNTIF(Quests[Set],'Set Counts'!A10) -> 1 | D10: =SUMIF(DeathCurses[],'Set Counts'!$A10,DeathCurses[Qty]) -> 0 | E10: =SUMIF(StoneCards[],'Set Counts'!$A10,StoneCards[Qty]) -> 14 | F10: =COUNTIF(Heroes[Set],'Set Counts'!$A10) -> 0 | G10: =COUNTIF(Monsters[Set],'Set Counts'!$A10) -> 0 | H10: =COUNTIF(Pets[Set],'Set Counts'!$A10) -> 0 | I10: =COUNTIF(Mounts[Set],'Set Counts'!$A10) -> 0 | J10: 2 | K10: =SUMIF(DragonTurns[],'Set Counts'!$A10,DragonTurns[Qty]) -> 24
A11: Poison Dragon | B11: =SUMIF(Upgrades[],'Set Counts'!$A11,Upgrades[QTY]) -> 27 | C11: =COUNTIF(Quests[Set],'Set Counts'!A11) -> 1 | D11: =SUMIF(DeathCurses[],'Set Counts'!$A11,DeathCurses[Qty]) -> 0 | E11: =SUMIF(StoneCards[],'Set Counts'!$A11,StoneCards[Qty]) -> 14 | F11: =COUNTIF(Heroes[Set],'Set Counts'!$A11) -> 0 | G11: =COUNTIF(Monsters[Set],'Set Counts'!$A11) -> 0 | H11: =COUNTIF(Pets[Set],'Set Counts'!$A11) -> 0 | I11: =COUNTIF(Mounts[Set],'Set Counts'!$A11) -> 0 | J11: 2 | K11: =SUMIF(DragonTurns[],'Set Counts'!$A11,DragonTurns[Qty]) -> 24
A12: The Nameless | B12: =SUMIF(Upgrades[],'Set Counts'!$A12,Upgrades[QTY]) -> 0 | C12: =COUNTIF(Quests[Set],'Set Counts'!A12) -> 3 | D12: =SUMIF(DeathCurses[],'Set Counts'!$A12,DeathCurses[Qty]) -> 0 | E12: =SUMIF(StoneCards[],'Set Counts'!$A12,StoneCards[Qty]) -> 0 | F12: =COUNTIF(Heroes[Set],'Set Counts'!$A12) -> 0 | G12: =COUNTIF(Monsters[Set],'Set Counts'!$A12) -> 12 | H12: =COUNTIF(Pets[Set],'Set Counts'!$A12) -> 0 | I12: =COUNTIF(Mounts[Set],'Set Counts'!$A12) -> 0 | J12: 0 | K12: =SUMIF(DragonTurns[],'Set Counts'!$A12,DragonTurns[Qty]) -> 0
A13: Whole Lotta Lava | B13: =SUMIF(Upgrades[],'Set Counts'!$A13,Upgrades[QTY]) -> 2 | C13: =COUNTIF(Quests[Set],'Set Counts'!A13) -> 3 | D13: =SUMIF(DeathCurses[],'Set Counts'!$A13,DeathCurses[Qty]) -> 0 | E13: =SUMIF(StoneCards[],'Set Counts'!$A13,StoneCards[Qty]) -> 0 | F13: =COUNTIF(Heroes[Set],'Set Counts'!$A13) -> 0 | G13: =COUNTIF(Monsters[Set],'Set Counts'!$A13) -> 12 | H13: =COUNTIF(Pets[Set],'Set Counts'!$A13) -> 0 | I13: =COUNTIF(Mounts[Set],'Set Counts'!$A13) -> 0 | J13: 0 | K13: =SUMIF(DragonTurns[],'Set Counts'!$A13,DragonTurns[Qty]) -> 0
A14: 2016 CMON Expo | B14: =SUMIF(Upgrades[],'Set Counts'!$A14,Upgrades[QTY]) -> 4 | C14: =COUNTIF(Quests[Set],'Set Counts'!A14) -> 0 | D14: =SUMIF(DeathCurses[],'Set Counts'!$A14,DeathCurses[Qty]) -> 0 | E14: =SUMIF(StoneCards[],'Set Counts'!$A14,StoneCards[Qty]) -> 0 | F14: =COUNTIF(Heroes[Set],'Set Counts'!$A14) -> 0 | G14: =COUNTIF(Monsters[Set],'Set Counts'!$A14) -> 0 | H14: =COUNTIF(Pets[Set],'Set Counts'!$A14) -> 0 | I14: =COUNTIF(Mounts[Set],'Set Counts'!$A14) -> 0 | J14: 0 | K14: =SUMIF(DragonTurns[],'Set Counts'!$A14,DragonTurns[Qty]) -> 0

Sheet Item Type by Set
A1: Item Types by Set | H1: Unique Items by Type and Level | Q1: Unique Count
H2: Type | I2: 1 | J2: 2 | K2: 3 | L2: 4 | M2: 5 | N2: 6 | O2: Total | Q2: Class | R2: 1 | S2: 2 | T2: 3 | U2: 4 | V2: 5 | W2: 6 | X2: Total
A3: Sum of QTY | H3: Sword | I3: =COUNTIFS(Upgrades!$H:$H,'Item Type by Set'!$H3,Upgrades!$D:$D,'Item Type by Set'!I$2) -> 2 | J3: =COUNTIFS(Upgrades!$H:$H,'Item Type by Set'!$H3,Upgrades!$D:$D,'Item Type by Set'!J$2) -> 2 | K3: =COUNTIFS(Upgrades!$H:$H,'Item Type by Set'!$H3,Upgrades!$D:$D,'Item Type by Set'!K$2) -> 1 | L3: =COUNTIFS(Upgrades!$H:$H,'Item Type by Set'!$H3,Upgrades!$D:$D,'Item Type by Set'!L$2) -> 2 | M3: =COUNTIFS(Upgrades!$H:$H,'Item Type by Set'!$H3,Upgrades!$D:$D,'Item Type by Set'!M$2) -> 2 | N3: =COUNTIFS(Upgrades!$H:$H,'Item Type by Set'!$H3,Upgrades!$D:$D,'Item Type by Set'!N$2) -> 3 | O3: =SUM(I3:N3) -> 12 | Q3: Boost | R3: =COUNTIFS(Upgrades!$G:$G,'Item Type by Set'!$Q3,Upgrades!$D:$D,'Item Type by Set'!I$2) -> 4 | S3: =COUNTIFS(Upgrades!$G:$G,'Item Type by Set'!$Q3,Upgrades!$D:$D,'Item Type by Set'!J$2) -> 3 | T3: =COUNTIFS(Upgrades!$G:$G,'Item Type by Set'!$Q3,Upgrades!$D:$D,'Item Type by Set'!K$2) -> 4 | U3: =COUNTIFS(Upgrades!$G:$G,'Item Type by Set'!$Q3,Upgrades!$D:$D,'Item Type by Set'!L$2) -> 5 | V3: =COUNTIFS(Upgrades!$G:$G,'Item Type by Set'!$Q3,Upgrades!$D:$D,'Item Type by Set'!M$2) -> 4 | W3: =COUNTIFS(Upgrades!$G:$G,'Item Type by Set'!$Q3,Upgrades!$D:$D,'Item Type by Set'!N$2) -> 11 | X3: =SUM(R3:W3) -> 31
A4: Set | B4: Type | C4: Level | D4: Total | H4: Axe | I4: =COUNTIFS(Upgrades!$H:$H,'Item Type by Set'!$H4,Upgrades!$D:$D,'Item Type by Set'!I$2) -> 1 | J4: =COUNTIFS(Upgrades!$H:$H,'Item Type by Set'!$H4,Upgrades!$D:$D,'Item Type by Set'!J$2) -> 1 | K4: =COUNTIFS(Upgrades!$H:$H,'Item Type by Set'!$H4,Upgrades!$D:$D,'Item Type by Set'!K$2) -> 0 | L4: =COUNTIFS(Upgrades!$H:$H,'Item Type by Set'!$H4,Upgrades!$D:$D,'Item Type by Set'!L$2) -> 1 | M4: =COUNTIFS(Upgrades!$H:$H,'Item Type by Set'!$H4,Upgrades!$D:$D,'Item Type by Set'!M$2) -> 0 | N4: =COUNTIFS(Upgrades!$H:$H,'Item Type by Set'!$H4,Upgrades!$D:$D,'Item Type by Set'!N$2) -> 1 | O4: =SUM(I4:N4) -> 4 | Q4: Pet Item | R4: =COUNTIFS(Upgrades!$G:$G,'Item Type by Set'!$Q4,Upgrades!$D:$D,'Item Type by Set'!I$2) -> 1 | S4: =COUNTIFS(Upgrades!$G:$G,'Item Type by Set'!$Q4,Upgrades!$D:$D,'Item Type by Set'!J$2) -> 1 | T4: =COUNTIFS(Upgrades!$G:$G,'Item Type by Set'!$Q4,Upgrades!$D:$D,'Item Type by Set'!K$2) -> 1 | U4: =COUNTIFS(Upgrades!$G:$G,'Item Type by Set'!$Q4,Upgrades!$D:$D,'Item Type by Set'!L$2) -> 0 | V4: =COUNTIFS(Upgrades!$G:$G,'Item Type by Set'!$Q4,Upgrades!$D:$D,'Item Type by Set'!M$2) -> 1 | W4: =COUNTIFS(Upgrades!$G:$G,'Item Type by Set'!$Q4,Upgrades!$D:$D,'Item Type by Set'!N$2) -> 0 | X4: =SUM(R4:W4) -> 4
A5: 2016 CMON Expo | B5: Bow | D5: 4 | H5: Hammer | I5: =COUNTIFS(Upgrades!$H:$H,'Item Type by Set'!$H5,Upgrades!$D:$D,'Item Type by Set'!I$2) -> 3 | J5: =COUNTIFS(Upgrades!$H:$H,'Item Type by Set'!$H5,Upgrades!$D:$D,'Item Type by Set'!J$2) -> 2 | K5: =COUNTIFS(Upgrades!$H:$H,'Item Type by Set'!$H5,Upgrades!$D:$D,'Item Type by Set'!K$2) -> 3 | L5: =COUNTIFS(Upgrades!$H:$H,'Item Type by Set'!$H5,Upgrades!$D:$D,'Item Type by Set'!L$2) -> 2 | M5: =COUNTIFS(Upgrades!$H:$H,'Item Type by Set'!$H5,Upgrades!$D:$D,'Item Type by Set'!M$2) -> 2 | N5: =COUNTIFS(Upgrades!$H:$H,'Item Type by Set'!$H5,Upgrades!$D:$D,'Item Type by Set'!N$2) -> 2 | O5: =SUM(I5:N5) -> 14 | Q5: Mount Item | R5: =COUNTIFS(Upgrades!$G:$G,'Item Type by Set'!$Q5,Upgrades!$D:$D,'Item Type by Set'!I$2) -> 1 | S5: =COUNTIFS(Upgrades!$G:$G,'Item Type by Set'!$Q5,Upgrades!$D:$D,'Item Type by Set'!J$2) -> 1 | T5: =COUNTIFS(Upgrades!$G:$G,'Item Type by Set'!$Q5,Upgrades!$D:$D,'Item Type by Set'!K$2) -> 1 | U5: =COUNTIFS(Upgrades!$G:$G,'Item Type by Set'!$Q5,Upgrades!$D:$D,'Item Type by Set'!L$2) -> 1 | V5: =COUNTIFS(Upgrades!$G:$G,'Item Type by Set'!$Q5,Upgrades!$D:$D,'Item Type by Set'!M$2) -> 1 | W5: =COUNTIFS(Upgrades!$G:$G,'Item Type by Set'!$Q5,Upgrades!$D:$D,'Item Type by Set'!N$2) -> 0 | X5: =SUM(R5:W5) -> 5
A6: 2016 CMON Expo Total | D6: 4 | H6: Bow | I6: =COUNTIFS(Upgrades!$H:$H,'Item Type by Set'!$H6,Upgrades!$D:$D,'Item Type by Set'!I$2) -> 2 | J6: =COUNTIFS(Upgrades!$H:$H,'Item Type by Set'!$H6,Upgrades!$D:$D,'Item Type by Set'!J$2) -> 3 | K6: =COUNTIFS(Upgrades!$H:$H,'Item Type by Set'!$H6,Upgrades!$D:$D,'Item Type by Set'!K$2) -> 2 | L6: =COUNTIFS(Upgrades!$H:$H,'Item Type by Set'!$H6,Upgrades!$D:$D,'Item Type by Set'!L$2) -> 3 | M6: =COUNTIFS(Upgrades!$H:$H,'Item Type by Set'!$H6,Upgrades!$D:$D,'Item Type by Set'!M$2) -> 3 | N6: =COUNTIFS(Upgrades!$H:$H,'Item Type by Set'!$H6,Upgrades!$D:$D,'Item Type by Set'!N$2) -> 3 | O6: =SUM(I6:N6) -> 16 | Q6: Total | R6: =SUM(R3:R5) -> 6 | S6: =SUM(S3:S5) -> 5 | T6: =SUM(T3:T5) -> 6 | U6: =SUM(U3:U5) -> 6 | V6: =SUM(V3:V5) -> 6 | W6: =SUM(W3:W5) -> 11
A7: Arcadia Quest | B7: Ability | D7: 8 | H7: Magic | I7: =COUNTIFS(Upgrades!$H:$H,'Item Type by Set'!$H7,Upgrades!$D:$D,'Item Type by Set'!I$2) -> 5 | J7: =COUNTIFS(Upgrades!$H:$H,'Item Type by Set'!$H7,Upgrades!$D:$D,'Item Type by Set'!J$2) -> 5 | K7: =COUNTIFS(Upgrades!$H:$H,'Item Type by Set'!$H7,Upgrades!$D:$D,'Item Type by Set'!K$2) -> 8 | L7: =COUNTIFS(Upgrades!$H:$H,'Item Type by Set'!$H7,Upgrades!$D:$D,'Item Type by Set'!L$2) -> 10 | M7: =COUNTIFS(Upgrades!$H:$H,'Item Type by Set'!$H7,Upgrades!$D:$D,'Item Type by Set'!M$2) -> 7 | N7: =COUNTIFS(Upgrades!$H:$H,'Item Type by Set'!$H7,Upgrades!$D:$D,'Item Type by Set'!N$2) -> 12 | O7: =SUM(I7:N7) -> 47
B8: Armor | D8: 10 | H8: Bling | I8: =COUNTIFS(Upgrades!$H:$H,'Item Type by Set'!$H8,Upgrades!$D:$D,'Item Type by Set'!I$2) -> 4 | J8: =COUNTIFS(Upgrades!$H:$H,'Item Type by Set'!$H8,Upgrades!$D:$D,'Item Type by Set'!J$2) -> 7 | K8: =COUNTIFS(Upgrades!$H:$H,'Item Type by Set'!$H8,Upgrades!$D:$D,'Item Type by Set'!K$2) -> 4 | L8: =COUNTIFS(Upgrades!$H:$H,'Item Type by Set'!$H8,Upgrades!$D:$D,'Item Type by Set'!L$2) -> 7 | M8: =COUNTIFS(Upgrades!$H:$H,'Item Type by Set'!$H8,Upgrades!$D:$D,'Item Type by Set'!M$2) -> 11 | N8: =COUNTIFS(Upgrades!$H:$H,'Item Type by Set'!$H8,Upgrades!$D:$D,'Item Type by Set'!N$2) -> 10 | O8: =SUM(I8:N8) -> 43 | Q8: Total Card Count
B9: Axe | D9: 8 | H9: Armor | I9: =COUNTIFS(Upgrades!$H:$H,'Item Type by Set'!$H9,Upgrades!$D:$D,'Item Type by Set'!I$2) -> 1 | J9: =COUNTIFS(Upgrades!$H:$H,'Item Type by Set'!$H9,Upgrades!$D:$D,'Item Type by Set'!J$2) -> 3 | K9: =COUNTIFS(Upgrades!$H:$H,'Item Type by Set'!$H9,Upgrades!$D:$D,'Item Type by Set'!K$2) -> 2 | L9: =COUNTIFS(Upgrades!$H:$H,'Item Type by Set'!$H9,Upgrades!$D:$D,'Item Type by Set'!L$2) -> 2 | M9: =COUNTIFS(Upgrades!$H:$H,'Item Type by Set'!$H9,Upgrades!$D:$D,'Item Type by Set'!M$2) -> 2 | N9: =COUNTIFS(Upgrades!$H:$H,'Item Type by Set'!$H9,Upgrades!$D:$D,'Item Type by Set'!N$2) -> 5 | O9: =SUM(I9:N9) -> 15 | Q9: Class | R9: 1 | S9: 2 | T9: 3 | U9: 4 | V9: 5 | W9: 6 | X9: Total
B10: Bling | D10: 26 | H10: Ability | I10: =COUNTIFS(Upgrades!$H:$H,'Item Type by Set'!$H10,Upgrades!$D:$D,'Item Type by Set'!I$2) -> 4 | J10: =COUNTIFS(Upgrades!$H:$H,'Item Type by Set'!$H10,Upgrades!$D:$D,'Item Type by Set'!J$2) -> 2 | K10: =COUNTIFS(Upgrades!$H:$H,'Item Type by Set'!$H10,Upgrades!$D:$D,'Item Type by Set'!K$2) -> 5 | L10: =COUNTIFS(Upgrades!$H:$H,'Item Type by Set'!$H10,Upgrades!$D:$D,'Item Type by Set'!L$2) -> 4 | M10: =COUNTIFS(Upgrades!$H:$H,'Item Type by Set'!$H10,Upgrades!$D:$D,'Item Type by Set'!M$2) -> 2 | N10: =COUNTIFS(Upgrades!$H:$H,'Item Type by Set'!$H10,Upgrades!$D:$D,'Item Type by Set'!N$2) -> 0 | O10: =SUM(I10:N10) -> 17 | Q10: Boost | R10: =SUMIFS(Upgrades!$C:$C,Upgrades!$G:$G,'Item Type by Set'!$Q10,Upgrades!$D:$D,'Item Type by Set'!R$9) -> 7 | S10: =SUMIFS(Upgrades!$C:$C,Upgrades!$G:$G,'Item Type by Set'!$Q10,Upgrades!$D:$D,'Item Type by Set'!S$9) -> 6 | T10: =SUMIFS(Upgrades!$C:$C,Upgrades!$G:$G,'Item Type by Set'!$Q10,Upgrades!$D:$D,'Item Type by Set'!T$9) -> 5 | U10: =SUMIFS(Upgrades!$C:$C,Upgrades!$G:$G,'Item Type by Set'!$Q10,Upgrades!$D:$D,'Item Type by Set'!U$9) -> 6 | V10: =SUMIFS(Upgrades!$C:$C,Upgrades!$G:$G,'Item Type by Set'!$Q10,Upgrades!$D:$D,'Item Type by Set'!V$9) -> 6 | W10: =SUMIFS(Upgrades!$C:$C,Upgrades!$G:$G,'Item Type by Set'!$Q10,Upgrades!$D:$D,'Item Type by Set'!W$9) -> 12 | X10: =SUM(R10:W10) -> 42
B11: Bow | D11: 15 | H11: Gear | I11: =COUNTIFS(Upgrades!$H:$H,'Item Type by Set'!$H11,Upgrades!$D:$D,'Item Type by Set'!I$2) -> 5 | J11: =COUNTIFS(Upgrades!$H:$H,'Item Type by Set'!$H11,Upgrades!$D:$D,'Item Type by Set'!J$2) -> 6 | K11: =COUNTIFS(Upgrades!$H:$H,'Item Type by Set'!$H11,Upgrades!$D:$D,'Item Type by Set'!K$2) -> 6 | L11: =COUNTIFS(Upgrades!$H:$H,'Item Type by Set'!$H11,Upgrades!$D:$D,'Item Type by Set'!L$2) -> 5 | M11: =COUNTIFS(Upgrades!$H:$H,'Item Type by Set'!$H11,Upgrades!$D:$D,'Item Type by Set'!M$2) -> 4 | N11: =COUNTIFS(Upgrades!$H:$H,'Item Type by Set'!$H11,Upgrades!$D:$D,'Item Type by Set'!N$2) -> 13 | O11: =SUM(I11:N11) -> 39 | Q11: Pet Item | R11: =SUMIFS(Upgrades!$C:$C,Upgrades!$G:$G,'Item Type by Set'!$Q11,Upgrades!$D:$D,'Item Type by Set'!R$9) -> 2 | S11: =SUMIFS(Upgrades!$C:$C,Upgrades!$G:$G,'Item Type by Set'!$Q11,Upgrades!$D:$D,'Item Type by Set'!S$9) -> 2 | T11: =SUMIFS(Upgrades!$C:$C,Upgrades!$G:$G,'Item Type by Set'!$Q11,Upgrades!$D:$D,'Item Type by Set'!T$9) -> 2 | U11: =SUMIFS(Upgrades!$C:$C,Upgrades!$G:$G,'Item Type by Set'!$Q11,Upgrades!$D:$D,'Item Type by Set'!U$9) -> 0 | V11: =SUMIFS(Upgrades!$C:$C,Upgrades!$G:$G,'Item Type by Set'!$Q11,Upgrades!$D:$D,'Item Type by Set'!V$9) -> 2 | W11: =SUMIFS(Upgrades!$C:$C,Upgrades!$G:$G,'Item Type by Set'!$Q11,Upgrades!$D:$D,'Item Type by Set'!W$9) -> 0 | X11: =SUM(R11:W11) -> 8
B12: Gear | D12: 19 | H12: Shield | I12: =COUNTIFS(Upgrades!$H:$H,'Item Type by Set'!$H12,Upgrades!$D:$D,'Item Type by Set'!I$2) -> 1 | J12: =COUNTIFS(Upgrades!$H:$H,'Item Type by Set'!$H12,Upgrades!$D:$D,'Item Type by Set'!J$2) -> 2 | K12: =COUNTIFS(Upgrades!$H:$H,'Item Type by Set'!$H12,Upgrades!$D:$D,'Item Type by Set'!K$2) -> 1 | L12: =COUNTIFS(Upgrades!$H:$H,'Item Type by Set'!$H12,Upgrades!$D:$D,'Item Type by Set'!L$2) -> 2 | M12: =COUNTIFS(Upgrades!$H:$H,'Item Type by Set'!$H12,Upgrades!$D:$D,'Item Type by Set'!M$2) -> 2 | N12: =COUNTIFS(Upgrades!$H:$H,'Item Type by Set'!$H12,Upgrades!$D:$D,'Item Type by Set'!N$2) -> 0 | O12: =SUM(I12:N12) -> 8 | Q12: Mount Item | R12: =SUMIFS(Upgrades!$C:$C,Upgrades!$G:$G,'Item Type by Set'!$Q12,Upgrades!$D:$D,'Item Type by Set'!R$9) -> 2 | S12: =SUMIFS(Upgrades!$C:$C,Upgrades!$G:$G,'Item Type by Set'!$Q12,Upgrades!$D:$D,'Item Type by Set'!S$9) -> 2 | T12: =SUMIFS(Upgrades!$C:$C,Upgrades!$G:$G,'Item Type by Set'!$Q12,Upgrades!$D:$D,'Item Type by Set'!T$9) -> 2 | U12: =SUMIFS(Upgrades!$C:$C,Upgrades!$G:$G,'Item Type by Set'!$Q12,Upgrades!$D:$D,'Item Type by Set'!U$9) -> 2 | V12: =SUMIFS(Upgrades!$C:$C,Upgrades!$G:$G,'Item Type by Set'!$Q12,Upgrades!$D:$D,'Item Type by Set'!V$9) -> 2 | W12: =SUMIFS(Upgrades!$C:$C,Upgrades!$G:$G,'Item Type by Set'!$Q12,Upgrades!$D:$D,'Item Type by Set'!W$9) -> 0 | X12: =SUM(R12:W12) -> 10
B13: Hammer | D13: 10 | H13: Thrown Weapon | I13: =COUNTIFS(Upgrades!$H:$H,'Item Type by Set'!$H13,Upgrades!$D:$D,'Item Type by Set'!I$2) -> 1 | J13: =COUNTIFS(Upgrades!$H:$H,'Item Type by Set'!$H13,Upgrades!$D:$D,'Item Type by Set'!J$2) -> 1 | K13: =COUNTIFS(Upgrades!$H:$H,'Item Type by Set'!$H13,Upgrades!$D:$D,'Item Type by Set'!K$2) -> 3 | L13: =COUNTIFS(Upgrades!$H:$H,'Item Type by Set'!$H13,Upgrades!$D:$D,'Item Type by Set'!L$2) -> 2 | M13: =COUNTIFS(Upgrades!$H:$H,'Item Type by Set'!$H13,Upgrades!$D:$D,'Item Type by Set'!M$2) -> 2 | N13: =COUNTIFS(Upgrades!$H:$H,'Item Type by Set'!$H13,Upgrades!$D:$D,'Item Type by Set'!N$2) -> 3 | O13: =SUM(I13:N13) -> 12 | Q13: Total | R13: =SUM(R10:R12) -> 11 | S13: =SUM(S10:S12) -> 10 | T13: =SUM(T10:T12) -> 9 | U13: =SUM(U10:U12) -> 8 | V13: =SUM(V10:V12) -> 10 | W13: =SUM(W10:W12) -> 12
B14: Lance | D14: 2 | H14: Lance | I14: =COUNTIFS(Upgrades!$H:$H,'Item Type by Set'!$H14,Upgrades!$D:$D,'Item Type by Set'!I$2) -> 1 | J14: =COUNTIFS(Upgrades!$H:$H,'Item Type by Set'!$H14,Upgrades!$D:$D,'Item Type by Set'!J$2) -> 1 | K14: =COUNTIFS(Upgrades!$H:$H,'Item Type by Set'!$H14,Upgrades!$D:$D,'Item Type by Set'!K$2) -> 0 | L14: =COUNTIFS(Upgrades!$H:$H,'Item Type by Set'!$H14,Upgrades!$D:$D,'Item Type by Set'!L$2) -> 1 | M14: =COUNTIFS(Upgrades!$H:$H,'Item Type by Set'!$H14,Upgrades!$D:$D,'Item Type by Set'!M$2) -> 0 | N14: =COUNTIFS(Upgrades!$H:$H,'Item Type by Set'!$H14,Upgrades!$D:$D,'Item Type by Set'!N$2) -> 1 | O14: =SUM(I14:N14) -> 4
B15: Magic | D15: 32 | H15: Exotic | I15: =COUNTIFS(Upgrades!$H:$H,'Item Type by Set'!$H15,Upgrades!$D:$D,'Item Type by Set'!I$2) -> 2 | J15: =COUNTIFS(Upgrades!$H:$H,'Item Type by Set'!$H15,Upgrades!$D:$D,'Item Type by Set'!J$2) -> 1 | K15: =COUNTIFS(Upgrades!$H:$H,'Item Type by Set'!$H15,Upgrades!$D:$D,'Item Type by Set'!K$2) -> 2 | L15: =COUNTIFS(Upgrades!$H:$H,'Item Type by Set'!$H15,Upgrades!$D:$D,'Item Type by Set'!L$2) -> 0 | M15: =COUNTIFS(Upgrades!$H:$H,'Item Type by Set'!$H15,Upgrades!$D:$D,'Item Type by Set'!M$2) -> 2 | N15: =COUNTIFS(Upgrades!$H:$H,'Item Type by Set'!$H15,Upgrades!$D:$D,'Item Type by Set'!N$2) -> 0 | O15: =SUM(I15:N15) -> 7 | Q15: Unique Boost & Pet/Mount Cards by Type
B16: Shield | D16: 6 | H16: Sword - Dragon | I16: =COUNTIFS(Upgrades!$H:$H,'Item Type by Set'!$H16,Upgrades!$D:$D,'Item Type by Set'!I$2) -> 0 | J16: =COUNTIFS(Upgrades!$H:$H,'Item Type by Set'!$H16,Upgrades!$D:$D,'Item Type by Set'!J$2) -> 0 | K16: =COUNTIFS(Upgrades!$H:$H,'Item Type by Set'!$H16,Upgrades!$D:$D,'Item Type by Set'!K$2) -> 0 | L16: =COUNTIFS(Upgrades!$H:$H,'Item Type by Set'!$H16,Upgrades!$D:$D,'Item Type by Set'!L$2) -> 0 | M16: =COUNTIFS(Upgrades!$H:$H,'Item Type by Set'!$H16,Upgrades!$D:$D,'Item Type by Set'!M$2) -> 0 | N16: =COUNTIFS(Upgrades!$H:$H,'Item Type by Set'!$H16,Upgrades!$D:$D,'Item Type by Set'!N$2) -> 1 | O16: =SUM(I16:N16) -> 1 | Q16: Type | R16: 1 | S16: 2 | T16: 3 | U16: 4 | V16: 5 | W16: 6 | X16: Total
B17: Sword | D17: 19 | H17: Gear - Dragon | I17: =COUNTIFS(Upgrades!$H:$H,'Item Type by Set'!$H17,Upgrades!$D:$D,'Item Type by Set'!I$2) -> 0 | J17: =COUNTIFS(Upgrades!$H:$H,'Item Type by Set'!$H17,Upgrades!$D:$D,'Item Type by Set'!J$2) -> 0 | K17: =COUNTIFS(Upgrades!$H:$H,'Item Type by Set'!$H17,Upgrades!$D:$D,'Item Type by Set'!K$2) -> 0 | L17: =COUNTIFS(Upgrades!$H:$H,'Item Type by Set'!$H17,Upgrades!$D:$D,'Item Type by Set'!L$2) -> 0 | M17: =COUNTIFS(Upgrades!$H:$H,'Item Type by Set'!$H17,Upgrades!$D:$D,'Item Type by Set'!M$2) -> 0 | N17: =COUNTIFS(Upgrades!$H:$H,'Item Type by Set'!$H17,Upgrades!$D:$D,'Item Type by Set'!N$2) -> 3 | O17: =SUM(I17:N17) -> 3 | Q17: Ability | R17: =SUMIFS(Upgrades!$C:$C,Upgrades!$G:$G,'Item Type by Set'!$Q17,Upgrades!$D:$D,'Item Type by Set'!R$9) -> 0 | S17: 1 | T17: 1 | U17: =SUMIFS(Upgrades!$C:$C,Upgrades!$G:$G,'Item Type by Set'!$Q17,Upgrades!$D:$D,'Item Type by Set'!U$9) -> 0 | V17: =SUMIFS(Upgrades!$C:$C,Upgrades!$G:$G,'Item Type by Set'!$Q17,Upgrades!$D:$D,'Item Type by Set'!V$9) -> 0 | W17: =SUMIFS(Upgrades!$C:$C,Upgrades!$G:$G,'Item Type by Set'!$Q17,Upgrades!$D:$D,'Item Type by Set'!W$9) -> 0 | X17: =SUM(R17:W17) -> 2
B18: Thrown Weapon | D18: 5 | H18: Lance - Dragon | I18: =COUNTIFS(Upgrades!$H:$H,'Item Type by Set'!$H18,Upgrades!$D:$D,'Item Type by Set'!I$2) -> 0 | J18: =COUNTIFS(Upgrades!$H:$H,'Item Type by Set'!$H18,Upgrades!$D:$D,'Item Type by Set'!J$2) -> 0 | K18: =COUNTIFS(Upgrades!$H:$H,'Item Type by Set'!$H18,Upgrades!$D:$D,'Item Type by Set'!K$2) -> 0 | L18: =COUNTIFS(Upgrades!$H:$H,'Item Type by Set'!$H18,Upgrades!$D:$D,'Item Type by Set'!L$2) -> 0 | M18: =COUNTIFS(Upgrades!$H:$H,'Item Type by Set'!$H18,Upgrades!$D:$D,'Item Type by Set'!M$2) -> 0 | N18: =COUNTIFS(Upgrades!$H:$H,'Item Type by Set'!$H18,Upgrades!$D:$D,'Item Type by Set'!N$2) -> 1 | O18: =SUM(I18:N18) -> 1 | Q18: Armor | R18: =SUMIFS(Upgrades!$C:$C,Upgrades!$G:$G,'Item Type by Set'!$Q18,Upgrades!$D:$D,'Item Type by Set'!R$9) -> 0 | S18: =SUMIFS(Upgrades!$C:$C,Upgrades!$G:$G,'Item Type by Set'!$Q18,Upgrades!$D:$D,'Item Type by Set'!S$9) -> 0 | T18: 1 | U18: =SUMIFS(Upgrades!$C:$C,Upgrades!$G:$G,'Item Type by Set'!$Q18,Upgrades!$D:$D,'Item Type by Set'!U$9) -> 0 | V18: =SUMIFS(Upgrades!$C:$C,Upgrades!$G:$G,'Item Type by Set'!$Q18,Upgrades!$D:$D,'Item Type by Set'!V$9) -> 0 | W18: =SUMIFS(Upgrades!$C:$C,Upgrades!$G:$G,'Item Type by Set'!$Q18,Upgrades!$D:$D,'Item Type by Set'!W$9) -> 0 | X18: =SUM(R18:W18) -> 1
A19: Arcadia Quest Total | D19: 160 | H19: Bow - Dragon | I19: =COUNTIFS(Upgrades!$H:$H,'Item Type by Set'!$H19,Upgrades!$D:$D,'Item Type by Set'!I$2) -> 0 | J19: =COUNTIFS(Upgrades!$H:$H,'Item Type by Set'!$H19,Upgrades!$D:$D,'Item Type by Set'!J$2) -> 0 | K19: =COUNTIFS(Upgrades!$H:$H,'Item Type by Set'!$H19,Upgrades!$D:$D,'Item Type by Set'!K$2) -> 0 | L19: =COUNTIFS(Upgrades!$H:$H,'Item Type by Set'!$H19,Upgrades!$D:$D,'Item Type by Set'!L$2) -> 0 | M19: =COUNTIFS(Upgrades!$H:$H,'Item Type by Set'!$H19,Upgrades!$D:$D,'Item Type by Set'!M$2) -> 0 | N19: =COUNTIFS(Upgrades!$H:$H,'Item Type by Set'!$H19,Upgrades!$D:$D,'Item Type by Set'!N$2) -> 2 | O19: =SUM(I19:N19) -> 2 | Q19: Bling | R19: 2 | S19: 1 | T19: 0 | U19: 2 | V19: 3 | W19: 6 | X19: =SUM(R19:W19) -> 14
A20: Beyond the Grave | B20: Ability | D20: 3 | H20: Armor - Dragon | I20: =COUNTIFS(Upgrades!$H:$H,'Item Type by Set'!$H20,Upgrades!$D:$D,'Item Type by Set'!I$2) -> 0 | J20: =COUNTIFS(Upgrades!$H:$H,'Item Type by Set'!$H20,Upgrades!$D:$D,'Item Type by Set'!J$2) -> 0 | K20: =COUNTIFS(Upgrades!$H:$H,'Item Type by Set'!$H20,Upgrades!$D:$D,'Item Type by Set'!K$2) -> 0 | L20: =COUNTIFS(Upgrades!$H:$H,'Item Type by Set'!$H20,Upgrades!$D:$D,'Item Type by Set'!L$2) -> 0 | M20: =COUNTIFS(Upgrades!$H:$H,'Item Type by Set'!$H20,Upgrades!$D:$D,'Item Type by Set'!M$2) -> 0 | N20: =COUNTIFS(Upgrades!$H:$H,'Item Type by Set'!$H20,Upgrades!$D:$D,'Item Type by Set'!N$2) -> 1 | O20: =SUM(I20:N20) -> 1 | Q20: Gear | R20: 4 | S20: 3 | T20: 4 | U20: 4 | V20: 3 | W20: 5 | X20: =SUM(R20:W20) -> 23
B21: Armor | D21: 2 | H21: Total | I21: =SUM(I3:I20) -> 32 | J21: =SUM(J3:J20) -> 36 | K21: =SUM(K3:K20) -> 37 | L21: =SUM(L3:L20) -> 41 | M21: =SUM(M3:M20) -> 39 | N21: =SUM(N3:N20) -> 61 | O21: 246 | Q21: Total | R21: =SUM(R17:R20) -> 6 | S21: =SUM(S17:S20) -> 5 | T21: =SUM(T17:T20) -> 6 | U21: =SUM(U17:U20) -> 6 | V21: =SUM(V17:V20) -> 6 | W21: =SUM(W17:W20) -> 11 | X21: 40
B22: Axe | D22: 4
B23: Bling | D23: 7
B24: Bow | D24: 4 | H24: Unique Items by Type and Level (Boosts, Pet/Mount Items Removed)
B25: Exotic | D25: 2 | H25: Type | I25: 1 | J25: 2 | K25: 3 | L25: 4 | M25: 5 | N25: 6 | O25: Total
B26: Gear | D26: 7 | H26: Sword | I26: =COUNTIFS(Upgrades!$H:$H,'Item Type by Set'!$H26,Upgrades!$D:$D,'Item Type by Set'!I$2) -> 2 | J26: =COUNTIFS(Upgrades!$H:$H,'Item Type by Set'!$H26,Upgrades!$D:$D,'Item Type by Set'!J$2) -> 2 | K26: =COUNTIFS(Upgrades!$H:$H,'Item Type by Set'!$H26,Upgrades!$D:$D,'Item Type by Set'!K$2) -> 1 | L26: =COUNTIFS(Upgrades!$H:$H,'Item Type by Set'!$H26,Upgrades!$D:$D,'Item Type by Set'!L$2) -> 2 | M26: =COUNTIFS(Upgrades!$H:$H,'Item Type by Set'!$H26,Upgrades!$D:$D,'Item Type by Set'!M$2) -> 2 | N26: =COUNTIFS(Upgrades!$H:$H,'Item Type by Set'!$H26,Upgrades!$D:$D,'Item Type by Set'!N$2) -> 3 | O26: =SUM(I26:N26) -> 12
B27: Hammer | D27: 1 | H27: Axe | I27: =COUNTIFS(Upgrades!$H:$H,'Item Type by Set'!$H27,Upgrades!$D:$D,'Item Type by Set'!I$2) -> 1 | J27: =COUNTIFS(Upgrades!$H:$H,'Item Type by Set'!$H27,Upgrades!$D:$D,'Item Type by Set'!J$2) -> 1 | K27: =COUNTIFS(Upgrades!$H:$H,'Item Type by Set'!$H27,Upgrades!$D:$D,'Item Type by Set'!K$2) -> 0 | L27: =COUNTIFS(Upgrades!$H:$H,'Item Type by Set'!$H27,Upgrades!$D:$D,'Item Type by Set'!L$2) -> 1 | M27: =COUNTIFS(Upgrades!$H:$H,'Item Type by Set'!$H27,Upgrades!$D:$D,'Item Type by Set'!M$2) -> 0 | N27: =COUNTIFS(Upgrades!$H:$H,'Item Type by Set'!$H27,Upgrades!$D:$D,'Item Type by Set'!N$2) -> 1 | O27: =SUM(I27:N27) -> 4
B28: Lance | D28: 2 | H28: Hammer | I28: =COUNTIFS(Upgrades!$H:$H,'Item Type by Set'!$H28,Upgrades!$D:$D,'Item Type by Set'!I$2) -> 3 | J28: =COUNTIFS(Upgrades!$H:$H,'Item Type by Set'!$H28,Upgrades!$D:$D,'Item Type by Set'!J$2) -> 2 | K28: =COUNTIFS(Upgrades!$H:$H,'Item Type by Set'!$H28,Upgrades!$D:$D,'Item Type by Set'!K$2) -> 3 | L28: =COUNTIFS(Upgrades!$H:$H,'Item Type by Set'!$H28,Upgrades!$D:$D,'Item Type by Set'!L$2) -> 2 | M28: =COUNTIFS(Upgrades!$H:$H,'Item Type by Set'!$H28,Upgrades!$D:$D,'Item Type by Set'!M$2) -> 2 | N28: =COUNTIFS(Upgrades!$H:$H,'Item Type by Set'!$H28,Upgrades!$D:$D,'Item Type by Set'!N$2) -> 2 | O28: =SUM(I28:N28) -> 14
B29: Magic | D29: 11 | H29: Bow | I29: =COUNTIFS(Upgrades!$H:$H,'Item Type by Set'!$H29,Upgrades!$D:$D,'Item Type by Set'!I$2) -> 2 | J29: =COUNTIFS(Upgrades!$H:$H,'Item Type by Set'!$H29,Upgrades!$D:$D,'Item Type by Set'!J$2) -> 3 | K29: =COUNTIFS(Upgrades!$H:$H,'Item Type by Set'!$H29,Upgrades!$D:$D,'Item Type by Set'!K$2) -> 2 | L29: =COUNTIFS(Upgrades!$H:$H,'Item Type by Set'!$H29,Upgrades!$D:$D,'Item Type by Set'!L$2) -> 3 | M29: =COUNTIFS(Upgrades!$H:$H,'Item Type by Set'!$H29,Upgrades!$D:$D,'Item Type by Set'!M$2) -> 3 | N29: =COUNTIFS(Upgrades!$H:$H,'Item Type by Set'!$H29,Upgrades!$D:$D,'Item Type by Set'!N$2) -> 3 | O29: =SUM(I29:N29) -> 16
B30: Shield | D30: 1 | H30: Magic | I30: =COUNTIFS(Upgrades!$H:$H,'Item Type by Set'!$H30,Upgrades!$D:$D,'Item Type by Set'!I$2) -> 5 | J30: =COUNTIFS(Upgrades!$H:$H,'Item Type by Set'!$H30,Upgrades!$D:$D,'Item Type by Set'!J$2) -> 5 | K30: =COUNTIFS(Upgrades!$H:$H,'Item Type by Set'!$H30,Upgrades!$D:$D,'Item Type by Set'!K$2) -> 8 | L30: =COUNTIFS(Upgrades!$H:$H,'Item Type by Set'!$H30,Upgrades!$D:$D,'Item Type by Set'!L$2) -> 10 | M30: =COUNTIFS(Upgrades!$H:$H,'Item Type by Set'!$H30,Upgrades!$D:$D,'Item Type by Set'!M$2) -> 7 | N30: =COUNTIFS(Upgrades!$H:$H,'Item Type by Set'!$H30,Upgrades!$D:$D,'Item Type by Set'!N$2) -> 12 | O30: =SUM(I30:N30) -> 47
B31: Sword | D31: 2 | H31: Bling | I31: =COUNTIFS(Upgrades!$H:$H,'Item Type by Set'!$H31,Upgrades!$D:$D,'Item Type by Set'!I$2)-R19 -> 2 | J31: =COUNTIFS(Upgrades!$H:$H,'Item Type by Set'!$H31,Upgrades!$D:$D,'Item Type by Set'!J$2)-S19 -> 6 | K31: =COUNTIFS(Upgrades!$H:$H,'Item Type by Set'!$H31,Upgrades!$D:$D,'Item Type by Set'!K$2)-T19 -> 4 | L31: =COUNTIFS(Upgrades!$H:$H,'Item Type by Set'!$H31,Upgrades!$D:$D,'Item Type by Set'!L$2)-U19 -> 5 | M31: =COUNTIFS(Upgrades!$H:$H,'Item Type by Set'!$H31,Upgrades!$D:$D,'Item Type by Set'!M$2)-V19 -> 8 | N31: =COUNTIFS(Upgrades!$H:$H,'Item Type by Set'!$H31,Upgrades!$D:$D,'Item Type by Set'!N$2)-W19 -> 4 | O31: =SUM(I31:N31) -> 29
B32: Thrown Weapon | D32: 2 | H32: Armor | I32: =COUNTIFS(Upgrades!$H:$H,'Item Type by Set'!$H32,Upgrades!$D:$D,'Item Type by Set'!I$2) -> 1 | J32: =COUNTIFS(Upgrades!$H:$H,'Item Type by Set'!$H32,Upgrades!$D:$D,'Item Type by Set'!J$2) -> 3 | K32: =COUNTIFS(Upgrades!$H:$H,'Item Type by Set'!$H32,Upgrades!$D:$D,'Item Type by Set'!K$2)-T18 -> 1 | L32: =COUNTIFS(Upgrades!$H:$H,'Item Type by Set'!$H32,Upgrades!$D:$D,'Item Type by Set'!L$2) -> 2 | M32: =COUNTIFS(Upgrades!$H:$H,'Item Type by Set'!$H32,Upgrades!$D:$D,'Item Type by Set'!M$2) -> 2 | N32: =COUNTIFS(Upgrades!$H:$H,'Item Type by Set'!$H32,Upgrades!$D:$D,'Item Type by Set'!N$2) -> 5 | O32: =SUM(I32:N32) -> 14
A33: Beyond the Grave Total | D33: 48 | H33: Ability | I33: =COUNTIFS(Upgrades!$H:$H,'Item Type by Set'!$H33,Upgrades!$D:$D,'Item Type by Set'!I$2) -> 4 | J33: =COUNTIFS(Upgrades!$H:$H,'Item Type by Set'!$H33,Upgrades!$D:$D,'Item Type by Set'!J$2)-S17 -> 1 | K33: =COUNTIFS(Upgrades!$H:$H,'Item Type by Set'!$H33,Upgrades!$D:$D,'Item Type by Set'!K$2)-T17 -> 4 | L33: =COUNTIFS(Upgrades!$H:$H,'Item Type by Set'!$H33,Upgrades!$D:$D,'Item Type by Set'!L$2) -> 4 | M33: =COUNTIFS(Upgrades!$H:$H,'Item Type by Set'!$H33,Upgrades!$D:$D,'Item Type by Set'!M$2) -> 2 | N33: =COUNTIFS(Upgrades!$H:$H,'Item Type by Set'!$H33,Upgrades!$D:$D,'Item Type by Set'!N$2) -> 0 | O33: =SUM(I33:N33) -> 15
A34: Chaos Dragon | B34: Armor | D34: 2 | H34: Gear | I34: =COUNTIFS(Upgrades!$H:$H,'Item Type by Set'!$H34,Upgrades!$D:$D,'Item Type by Set'!I$2)-R20 -> 1 | J34: =COUNTIFS(Upgrades!$H:$H,'Item Type by Set'!$H34,Upgrades!$D:$D,'Item Type by Set'!J$2)-S20 -> 3 | K34: =COUNTIFS(Upgrades!$H:$H,'Item Type by Set'!$H34,Upgrades!$D:$D,'Item Type by Set'!K$2)-T20 -> 2 | L34: =COUNTIFS(Upgrades!$H:$H,'Item Type by Set'!$H34,Upgrades!$D:$D,'Item Type by Set'!L$2)-U20 -> 1 | M34: =COUNTIFS(Upgrades!$H:$H,'Item Type by Set'!$H34,Upgrades!$D:$D,'Item Type by Set'!M$2)-V20 -> 1 | N34: =COUNTIFS(Upgrades!$H:$H,'Item Type by Set'!$H34,Upgrades!$D:$D,'Item Type by Set'!N$2)-W20 -> 8 | O34: =SUM(I34:N34) -> 16
B35: Axe | D35: 2 | H35: Shield | I35: =COUNTIFS(Upgrades!$H:$H,'Item Type by Set'!$H35,Upgrades!$D:$D,'Item Type by Set'!I$2) -> 1 | J35: =COUNTIFS(Upgrades!$H:$H,'Item Type by Set'!$H35,Upgrades!$D:$D,'Item Type by Set'!J$2) -> 2 | K35: =COUNTIFS(Upgrades!$H:$H,'Item Type by Set'!$H35,Upgrades!$D:$D,'Item Type by Set'!K$2) -> 1 | L35: =COUNTIFS(Upgrades!$H:$H,'Item Type by Set'!$H35,Upgrades!$D:$D,'Item Type by Set'!L$2) -> 2 | M35: =COUNTIFS(Upgrades!$H:$H,'Item Type by Set'!$H35,Upgrades!$D:$D,'Item Type by Set'!M$2) -> 2 | N35: =COUNTIFS(Upgrades!$H:$H,'Item Type by Set'!$H35,Upgrades!$D:$D,'Item Type by Set'!N$2) -> 0 | O35: =SUM(I35:N35) -> 8
B36: Bling | D36: 3 | H36: Thrown Weapon | I36: =COUNTIFS(Upgrades!$H:$H,'Item Type by Set'!$H36,Upgrades!$D:$D,'Item Type by Set'!I$2) -> 1 | J36: =COUNTIFS(Upgrades!$H:$H,'Item Type by Set'!$H36,Upgrades!$D:$D,'Item Type by Set'!J$2) -> 1 | K36: =COUNTIFS(Upgrades!$H:$H,'Item Type by Set'!$H36,Upgrades!$D:$D,'Item Type by Set'!K$2) -> 3 | L36: =COUNTIFS(Upgrades!$H:$H,'Item Type by Set'!$H36,Upgrades!$D:$D,'Item Type by Set'!L$2) -> 2 | M36: =COUNTIFS(Upgrades!$H:$H,'Item Type by Set'!$H36,Upgrades!$D:$D,'Item Type by Set'!M$2) -> 2 | N36: =COUNTIFS(Upgrades!$H:$H,'Item Type by Set'!$H36,Upgrades!$D:$D,'Item Type by Set'!N$2) -> 3 | O36: =SUM(I36:N36) -> 12
B37: Bow | D37: 2 | H37: Lance | I37: =COUNTIFS(Upgrades!$H:$H,'Item Type by Set'!$H37,Upgrades!$D:$D,'Item Type by Set'!I$2) -> 1 | J37: =COUNTIFS(Upgrades!$H:$H,'Item Type by Set'!$H37,Upgrades!$D:$D,'Item Type by Set'!J$2) -> 1 | K37: =COUNTIFS(Upgrades!$H:$H,'Item Type by Set'!$H37,Upgrades!$D:$D,'Item Type by Set'!K$2) -> 0 | L37: =COUNTIFS(Upgrades!$H:$H,'Item Type by Set'!$H37,Upgrades!$D:$D,'Item Type by Set'!L$2) -> 1 | M37: =COUNTIFS(Upgrades!$H:$H,'Item Type by Set'!$H37,Upgrades!$D:$D,'Item Type by Set'!M$2) -> 0 | N37: =COUNTIFS(Upgrades!$H:$H,'Item Type by Set'!$H37,Upgrades!$D:$D,'Item Type by Set'!N$2) -> 1 | O37: =SUM(I37:N37) -> 4
B38: Gear | D38: 5 | H38: Exotic | I38: =COUNTIFS(Upgrades!$H:$H,'Item Type by Set'!$H38,Upgrades!$D:$D,'Item Type by Set'!I$2) -> 2 | J38: =COUNTIFS(Upgrades!$H:$H,'Item Type by Set'!$H38,Upgrades!$D:$D,'Item Type by Set'!J$2) -> 1 | K38: =COUNTIFS(Upgrades!$H:$H,'Item Type by Set'!$H38,Upgrades!$D:$D,'Item Type by Set'!K$2) -> 2 | L38: =COUNTIFS(Upgrades!$H:$H,'Item Type by Set'!$H38,Upgrades!$D:$D,'Item Type by Set'!L$2) -> 0 | M38: =COUNTIFS(Upgrades!$H:$H,'Item Type by Set'!$H38,Upgrades!$D:$D,'Item Type by Set'!M$2) -> 2 | N38: =COUNTIFS(Upgrades!$H:$H,'Item Type by Set'!$H38,Upgrades!$D:$D,'Item Type by Set'!N$2) -> 0 | O38: =SUM(I38:N38) -> 7
B39: Gear - Dragon | D39: 2 | H39: Sword - Dragon | I39: =COUNTIFS(Upgrades!$H:$H,'Item Type by Set'!$H39,Upgrades!$D:$D,'Item Type by Set'!I$2) -> 0 | J39: =COUNTIFS(Upgrades!$H:$H,'Item Type by Set'!$H39,Upgrades!$D:$D,'Item Type by Set'!J$2) -> 0 | K39: =COUNTIFS(Upgrades!$H:$H,'Item Type by Set'!$H39,Upgrades!$D:$D,'Item Type by Set'!K$2) -> 0 | L39: =COUNTIFS(Upgrades!$H:$H,'Item Type by Set'!$H39,Upgrades!$D:$D,'Item Type by Set'!L$2) -> 0 | M39: =COUNTIFS(Upgrades!$H:$H,'Item Type by Set'!$H39,Upgrades!$D:$D,'Item Type by Set'!M$2) -> 0 | N39: =COUNTIFS(Upgrades!$H:$H,'Item Type by Set'!$H39,Upgrades!$D:$D,'Item Type by Set'!N$2) -> 1 | O39: =SUM(I39:N39) -> 1
B40: Magic | D40: 6 | H40: Gear - Dragon | I40: =COUNTIFS(Upgrades!$H:$H,'Item Type by Set'!$H40,Upgrades!$D:$D,'Item Type by Set'!I$2) -> 0 | J40: =COUNTIFS(Upgrades!$H:$H,'Item Type by Set'!$H40,Upgrades!$D:$D,'Item Type by Set'!J$2) -> 0 | K40: =COUNTIFS(Upgrades!$H:$H,'Item Type by Set'!$H40,Upgrades!$D:$D,'Item Type by Set'!K$2) -> 0 | L40: =COUNTIFS(Upgrades!$H:$H,'Item Type by Set'!$H40,Upgrades!$D:$D,'Item Type by Set'!L$2) -> 0 | M40: =COUNTIFS(Upgrades!$H:$H,'Item Type by Set'!$H40,Upgrades!$D:$D,'Item Type by Set'!M$2) -> 0 | N40: =COUNTIFS(Upgrades!$H:$H,'Item Type by Set'!$H40,Upgrades!$D:$D,'Item Type by Set'!N$2) -> 3 | O40: =SUM(I40:N40) -> 3
...

Sheet Upgrades
A1: Set | B1: Number | C1: QTY | D1: Level | E1: Name | F1: Price | G1: Class | H1: Type | I1: ATK | J1: DEF | K1: HP | L1: Reroll | M1: Description
A2: Arcadia Quest | B2: 1-01 | C2: 3 | D2: 1 | E2: Trusty Blade | F2: 1 | G2: Melee Attack | H2: Sword | I2: 3 | J2: 1 | L2: 1
A3: Arcadia Quest | B3: 1-02 | C3: 2 | D3: 1 | E3: Bleeder | F3: 2 | G3: Melee Attack | H3: Axe | I3: 3 | M3: Each Crit deals one additional hit.
A4: Arcadia Quest | B4: 1-03 | C4: 1 | D4: 1 | E4: Orc Beater | F4: 8 | G4: Melee Attack | H4: Hammer | I4: 4 | M4: Rolls +1 die against Orcs and Goblins.
A5: Arcadia Quest | B5: 1-04 | C5: 3 | D5: 1 | E5: Crescent Bow | F5: 3 | G5: Ranged Attack | H5: Bow | I5: 3
A6: Arcadia Quest | B6: 1-05 | C6: 3 | D6: 1 | E6: Wind Blast | F6: 4 | G6: Ranged Attack | H6: Magic | I6: 3 | M6: If this rolls any hits, move the target up to 3 spaces (this Move doesn't trigger Guard Reaction).
A7: Arcadia Quest | B7: 1-06 | C7: 2 | D7: 1 | E7: Sun Ring | F7: 0 | G7: Permanent | H7: Bling | L7: 1
A8: Arcadia Quest | B8: 1-07 | C8: 2 | D8: 1 | E8: Moon Ring | F8: 4 | G8: Boost | H8: Bling | M8: +1 die to one Attack Card.
A9: Arcadia Quest | B9: 1-08 | C9: 2 | D9: 1 | E9: Orc Pelt | F9: 5 | G9: Permanent | H9: Armor | J9: 2 | M9: Limit 1 armor per Hero.
A10: Arcadia Quest | B10: 1-09 | C10: 2 | D10: 1 | E10: Grrrrrrrrr! | F10: 7 | G10: Permanent | H10: Ability | M10: Once per attack, you may take 1 Wound to add +1 die.
A11: Arcadia Quest | B11: 1-10 | C11: 2 | D11: 1 | E11: Cleave | F11: 5 | G11: Permanent | H11: Ability | M11: Your Sword and Axe attacks may target an additional Enemy Close to this Hero.
A12: Arcadia Quest | B12: 1-11 | C12: 2 | D12: 1 | E12: Das Boot | F12: 0 | G12: Permanent | H12: Gear | M12: When you activate a different Hero, you may move this Hero 1 Space.
A13: Arcadia Quest | B13: 2-01 | C13: 2 | D13: 2 | E13: Smashface | F13: 1 | G13: Melee Attack | H13: Hammer | I13: 4 | M13: If this deals any Wounds, your target is Dazed.
A14: Arcadia Quest | B14: 2-02 | C14: 2 | D14: 2 | E14: Quickshot | F14: 4 | G14: Ranged Attack | H14: Bow | I14: 3 | M14: Only Crit on the Defense roll score saves against this attack.
A15: Arcadia Quest | B15: 2-03 | C15: 2 | D15: 2 | E15: Life Drain II | F15: 3 | G15: Ranged Attack | H15: Magic | I15: 3 | M15: Each hit heals 1 Wound from this Hero and one Close Ally.
A16: Arcadia Quest | B16: 2-04 | C16: 3 | D16: 2 | E16: Decimator | F16: 2 | G16: Melee Attack | H16: Axe | I16: 4 | M16: Each Crit deals one additional hit.
A17: Arcadia Quest | B17: 2-05 | C17: 2 | D17: 2 | E17: Hate | F17: 4 | G17: Ranged Attack | H17: Magic | I17: 3 | M17: If this rolls any Crit against a Hero, exhaust all of his cards, unless he takes 2 extra Wounds.
A18: Arcadia Quest | B18: 2-06 | C18: 2 | D18: 2 | E18: Knight's Plate | F18: 6 | G18: Permanent | H18: Armor | J18: 2 | K18: 1 | M18: Limit 1 armor per Hero.
A19: Arcadia Quest | B19: 2-07 | C19: 1 | D19: 2 | E19: Knight's Shield | F19: 1 | G19: Permanent | H19: Shield | J19: 1 | M19: May exhaust your Hero card to force an attack made against you to be rolled again.
A20: Arcadia Quest | B20: 2-08 | C20: 1 | D20: 2 | E20: Amulet of Retribution | F20: 8 | G20: Permanent | H20: Bling | M20: Each hit cancelled by this Hero's Defense roll deals 1 Wound to the attacker.
A21: Arcadia Quest | B21: 2-09 | C21: 2 | D21: 2 | E21: Heart of the Unicorn | F21: 0 | G21: Permanent | H21: Bling | K21: 2 | L21: 1
A22: Beyond the Grave | B22: BG1-03 | C22: 2 | D22: 1 | E22: Deadshot | F22: 3 | G22: Boost | H22: Gear | M22: +1 die to a Bow attack and an extra +1 die per Death Token on this Hero.
A23: Arcadia Quest | B23: 2-11 | C23: 1 | D23: 2 | E23: Cloak of Displacement | F23: 1 | G23: Permanent | H23: Gear | M23: At the start of your turn, you may switch places between this Hero and an Ally (drop all Quest tokens).
A24: Arcadia Quest | B24: 2-12 | C24: 1 | D24: 2 | E24: Celerity Stick | F24: 6 | G24: Permanent | H24: Gear | M24: This Hero may take 1 Wound to unexhaust all of his cards.
A25: Inferno | B25: INF1-10 | C25: 1 | D25: 1 | E25: Healing Bracer | F25: 0 | G25: Boost | H25: Gear | M25: Each wound dealt by the boosted Melee Attack heals 1 Wound from this Hero.
A26: Arcadia Quest | B26: 2-14 | C26: 1 | D26: 2 | E26: Crack of Dawn | F26: 9 | G26: Melee Attack | H26: Hammer | I26: 4 | M26: Rolls +1 die against Heroes.
A27: Arcadia Quest | B27: 3-01 | C27: 2 | D27: 3 | E27: Night Fury | F27: 3 | G27: Melee Attack | H27: Sword | I27: 4 | J27: 2 | L27: 2
A28: Arcadia Quest | B28: 3-02 | C28: 2 | D28: 3 | E28: Thorn | F28: 3 | G28: Ranged Attack | H28: Bow | I28: 4
A29: Arcadia Quest | B29: 3-03 | C29: 2 | D29: 3 | E29: Brimstone | F29: 1 | G29: Melee Attack | H29: Hammer | I29: 4 | M29: If this deals any Wounds, your target and 1 additional Enemy Close to it are Dazed.
A30: Arcadia Quest | B30: 3-04 | C30: 1 | D30: 3 | E30: Da Bomb | F30: 9 | G30: Ranged Attack | H30: Thrown Weapon | I30: 3 | M30: Limit 1 Bomb per Guild. If this rolls any hits, place 1 Guild token on each Close Space. Token explodes and attacks an enemy Hero who moves into that Space.
A31: Arcadia Quest | B31: 3-05 | C31: 2 | D31: 3 | E31: Nova Bolt II | F31: 4 | G31: Ranged Attack | H31: Magic | I31: 4 | M31: If this rolls any Crit, may target an additional Enemy Close to the target
A32: Arcadia Quest | B32: 3-06 | C32: 1 | D32: 3 | E32: Astral Strike | F32: 6 | G32: Melee Attack | H32: Magic | I32: 3 | M32: Only targets any Enemy on the board that's Close to an Ally of yours. (May be used by a dead Hero. Does not trigger Payback Reaction.)
A33: Arcadia Quest | B33: 3-07 | C33: 2 | D33: 3 | E33: Wind Blast II | F33: 4 | G33: Ranged Attack | H33: Magic | I33: 4 | M33: If this rolls any hits, move the target up to 3 spaces (this Move doesn't trigger Guard Reaction).
A34: Arcadia Quest | B34: 3-08 | C34: 1 | D34: 3 | E34: Die Booten | F34: 2 | G34: Permanent | H34: Gear | M34: When you activate a different Hero, you may move this Hero 2 Spaces.
A35: Arcadia Quest | B35: 3-09 | C35: 1 | D35: 3 | E35: More Grrrrrrrrr! | F35: 4 | G35: Permanent | H35: Ability | M35: Once per attack, you may take 2 Wounds to add +2 die.
A36: Arcadia Quest | B36: 3-10 | C36: 1 | D36: 3 | E36: Heart of the Gryphon | F36: 0 | G36: Permanent | H36: Bling | K36: 3
A37: Arcadia Quest | B37: 3-11 | C37: 1 | D37: 3 | E37: Genesis Glass | F37: 8 | G37: Permanent | H37: Bling | M37: At the start of your turn, this Hero heals 1 Wound.
A38: Arcadia Quest | B38: 3-12 | C38: 2 | D38: 3 | E38: Lord's Plate | F38: 6 | G38: Permanent | H38: Armor | J38: 4 | K38: 1 | M38: Limit 1 armor per Hero.
A39: Arcadia Quest | B39: 3-13 | C39: 2 | D39: 3 | E39: Sun Ring II | F39: 0 | G39: Permanent | H39: Bling | L39: 3
A40: Arcadia Quest | B40: 3-14 | C40: 2 | D40: 3 | E40: Battle Cry | F40: 4 | G40: Permanent | H40: Ability | M40: If your attack rolls any Crit, you may activate another allied Hero this turn.
...

Sheet Quests
A1: Set | B1: Quest | C1: Description
A2: Arcadia Quest | B2: Aid the Resistance | C2: Escort the Blue or Orange Quest token to the indicated area.
A3: Arcadia Quest | B3: Close the Gate | C3: Step on Red or Green to help close the gate (remove 1 Spawn point).
A4: Arcadia Quest | B4: Destroy One Stone | C4: Collect 1 Quest token.
A5: Arcadia Quest | B5: Find the Lost Weapons | C5: Collect 1 Quest token.
A6: Arcadia Quest | B6: Find the Tomes | C6: Collect 2 Quest tokens.
A7: Arcadia Quest | B7: Kill 3 Monsters | C7: Kill any 3 Monsters.
A8: Arcadia Quest | B8: Kill Blue | C8: Kill one Hero from opposing Blue Guild.
A9: Arcadia Quest | B9: Kill Green | C9: Kill one Hero from opposing Green Guild.
A10: Arcadia Quest | B10: Kill Hammer Beastman | C10: Kill a Hammer Beastman.
A11: Arcadia Quest | B11: Kill Lord Fang | C11: Kill Lord Fang.
A12: Arcadia Quest | B12: Kill one Sister | C12: Kill either a Sister of Pain or a Sister of Pleasure.
... A105: Whole Lotta Lava | B105: Stop the Eruption | C105: Have 2 Heroes at the same time at the designated area of the map.

Sheet Death Curses
A1: Set | B1: Number | C1: Qty | D1: Value | E1: Name | F1: Description
A2: Arcadia Quest | B2: D-00 | C2: 10 | D2: 0 | E2: No Curse | F2: Nothing happens, discard this card.
A3: Arcadia Quest | B3: D-01 | C3: 1 | D3: 1 | E3: Aquaphobia | F3: This Hero cannot use Potion tokens.
A4: Arcadia Quest | B4: D-02 | C4: 4 | D4: 2 | E4: System Shock | F4: Occupies a card slot. No other card effect.
A5: Arcadia Quest | B5: D-03 | C5: 2 | D5: 3 | E5: Nosebleed | F5: -1 Life
A6: Arcadia Quest | B6: D-04 | C6: 3 | D6: 4 | E6: Amnesia | F6: Place on Hero card. This Hero loses his Natural Ability.
A7: Arcadia Quest | B7: D-05 | C7: 2 | D7: 5 | E7: Severe Nosebleed | F7: Occupies a card slot. -1 Life
A8: Arcadia Quest | B8: D-06 | C8: 1 | D8: 6 | E8: Accident Prone | F8: This Hero suffers 1 Wound if his attack deals no Wounds.
A9: Arcadia Quest | B9: D-07 | C9: 1 | D9: 7 | E9: Dazed and Confused | F9: If this Hero suffers at least 1 Wound, he is Dazed.
A10: Inferno | B10: INFD-00 | C10: 10 | D10: 0 | E10: No Curse | F10: Nothing happens, discard this card.
A11: Inferno | B11: INFD-01 | C11: 3 | D11: 1 | E11: Damned | F11: 1 Damnation
A12: Inferno | B12: INFD-02 | C12: 2 | D12: 2 | E12: System Shock | F12: Occupies a card slot. No other card effect.
A13: Inferno | B13: INFD-03 | C13: 3 | D13: 3 | E13: Sinful | F13: Each time this Hero gains any number of Damnation, he gets 1 additional Damnation.
... A17: Inferno | B17: INFD-07 | C17: 1 | D17: 7 | E17: Eternally Damned | F17: Occupies a Card slot. 3 Damnation

Sheet Stone Cards
A1: Set | B1: Number | C1: Qty | D1: Name | E1: Type | F1: Description
A2: Beyond the Grave | B2: TS-01 | C2: 2 | D2: Minion on the Prowl | E2: Tombstone | F2: Activate a Minor Minion, performing its movement and/or attack against any Hero of your choice.
A3: Beyond the Grave | B3: TS-02 | C3: 2 | D3: Minion on the Prowl | E3: Tombstone | F3: Activate a Minion of any type, performing its movement and/or attack against any Hero of your choice.
A4: Beyond the Grave | B4: TS-03 | C4: 1 | D4: Villain on the Prowl | E4: Tombstone | F4: Activate a Minor Villain or a Minion of any type, performing its movement and/or attack against any Hero of your choice.
A5: Beyond the Grave | B5: TS-04 | C5: 1 | D5: Villain on the Prowl | E5: Tombstone | F5: Activate a Villain or Minion of any type, performing its movement and/or attack against any Hero of your choice.
A6: Beyond the Grave | B6: TS-05 | C6: 1 | D6: Banishment | E6: Tombstone | F6: Take any Minor Minion from the board and place it in the Spawn tile. (This does not count as a kill.)
A7: Beyond the Grave | B7: TS-06 | C7: 1 | D7: Reckoning | E7: Tombstone | F7: All Enemy Heroes whose figure is currently place on its Hero Card receives 1 extra Death token.
A8: Beyond the Grave | B8: TS-07 | C8: 1 | D8: Mounting Dread | E8: Tombstone | F8: All other players must exhaust one Attack card from one of their living Heroes.
A9: Beyond the Grave | B9: TS-08 | C9: 1 | D9: Ray of Hope | E9: Tombstone | F9: All Heroes in your Guild may heal 1 Wound and you may remove 1 Death Curse from a Hero.
A10: Beyond the Grave | B10: TS-09 | C10: 1 | D10: Acid Rain | E10: Tombstone | F10: All Enemy Heroes that are in an outdoor Space suffer 1 Wound.
A11: Beyond the Grave | B11: TS-10 | C11: 1 | D11: Just a Flesh Wound | E11: Tombstone | F11: Select any 2 Monsters and heal 2 Wounds from each.
A12: Beyond the Grave | B12: TS-11 | C12: 1 | D12: Hidden Stash | E12: Tombstone | F12: Draw a card from the last Upgrade Deck that was accessed and give it to any of your Heroes.
A13: Beyond the Grave | B13: TS-12 | C13: 1 | D13: Wake the Dead | E13: Tombstone | F13: The first Monster from the Spawn tile is placed in this Space and immediately attacks the active Hero (if the Space is Full, place it in a Close Space).
... A41: Poison Dragon | B41: PO-DS-04 | C41: 2 | D41: Noxious Fog | E41: Dragonstone | F41: All Outdoor Enemy Heroes take 1 Poison token.

Sheet Heroes
A1: Set | B1: Name | C1: DEF | D1: HP | E1: Ability Name | F1: Ability Description
A2: 2017 GenCon | B2: Princess Pearl | C2: 2 | D2: 3 | F2: Exhaust hero to un-exhaust a hero in line of sight.
A3: Arcadia Quest | B3: Diva | C3: 4 | D3: 4 | E3: Tough as Nails | F3: (No ability)
A4: Arcadia Quest | B4: Greensleeves | C4: 2 | D4: 4 | E4: Bow Mastery | F4: When attacking with a Bow attack card, each Crit deals one additional hit.
A5: Arcadia Quest | B5: Grom | C5: 1 | D5: 5 | E5: Berserk | F5: Roll +1 die in all rolls while wounded.
A6: Arcadia Quest | B6: Hobsbawm | C6: 2 | D6: 4 | E6: Blessing | F6: If he uses a Magic attack card and does not perform his Movement, you may activate another Ally within Line of Sight.
A7: Arcadia Quest | B7: Johan | C7: 3 | D7: 3 | E7: Blade Throw | F7: May use Sword attack cards as Ranged attack cards (you still need Melee icons to hit).
A8: Arcadia Quest | B8: Kanga | C8: 2 | D8: 4 | E8: Self-Sacrifice | F8: May take a Wound instead of exhausting a card.
A9: Arcadia Quest | B9: Maya | C9: 1 | D9: 5 | E9: Mana Mastery | F9: May exhaust each Magic attack card twice.
A10: Arcadia Quest | B10: Scarlet | C10: 3 | D10: 3 | E10: Backstab | F10: Roll +1 die when attacking a flanked target (a target with at least one other Enemy Close to it).
A11: Arcadia Quest | B11: Seth | C11: 2 | D11: 3 | E11: Piercing Magic | F11: When attacking with a Magic card, the target does not roll Defense dice.
A12: Arcadia Quest | B12: Spike | C12: 2 | D12: 3 | E12: Vengeance | F12: Each Crit on his Defense roll deals 1 Wound to the attacker.
A13: Arcadia Quest | B13: Wisp | C13: 2 | D13: 3 | E13: Stealth | F13: When moving, does not trigger Guard Reaction.
A14: Arcadia Quest | B14: Zazu | C14: 2 | D14: 4 | E14: Opportunist | F14: Does not exhaust an attack card when attacking a flanked target (a target with at least one other Enemy Close to it).
... A145: Usagi Yojimbo Hero Pack | B145: Kitsune | C145: 3 | D145: 3 | E145: Pick Pocket | F145: When Kitsune kills an enemy Hero, she gains 2 additional coins per Quest that the targeted Hero's Guild has accomplished.

Sheet Monsters
A1: Set | B1: Name | C1: Type | D1: Level | E1: Life | F1: Overkill | G1: Defense | H1: Re-roll | I1: Coins | J1: Move | K1: Attack Type | L1: Attack | M1: Attack Name | N1: Ability
A2: Arcadia Quest | B2: Goblin Archer | C2: Minor Minion | D2: 1 | E2: 1 | F2: 2 | I2: 1 | J2: 1 | K2: Ranged | L2: 2 | M2: Arrow to the Knee
A3: Arcadia Quest | B3: Goblin Archer | C3: Minor Minion | D3: 2-3 | E3: 2 | F3: 3 | I3: 1 | J3: 1 | K3: Ranged | L3: 2 | M3: Arrow to the Knee
A4: Arcadia Quest | B4: Goblin Archer | C4: Minor Minion | D4: 4-5 | E4: 3 | F4: 4 | I4: 1 | J4: 1 | K4: Ranged | L4: 3 | M4: Arrow to the Knee
A5: Arcadia Quest | B5: Goblin Archer | C5: Minor Minion | D5: 6 | E5: 4 | F5: 5 | I5: 1 | J5: 1 | K5: Ranged | L5: 3 | M5: Arrow to the Knee
A6: Arcadia Quest | B6: Orc Marauder | C6: Minor Minion | D6: 1 | E6: 2 | F6: 3 | I6: 1 | J6: 1 | K6: Melee | L6: 3 | M6: Hack n' Slash
A7: Arcadia Quest | B7: Orc Marauder | C7: Minor Minion | D7: 2-3 | E7: 3 | F7: 4 | I7: 1 | J7: 1 | K7: Melee | L7: 3 | M7: Hack n' Slash
A8: Arcadia Quest | B8: Orc Marauder | C8: Minor Minion | D8: 4-5 | E8: 4 | F8: 5 | I8: 1 | J8: 1 | K8: Melee | L8: 4 | M8: Hack n' Slash
A9: Arcadia Quest | B9: Orc Marauder | C9: Minor Minion | D9: 6 | E9: 5 | F9: 6 | I9: 1 | J9: 1 | K9: Melee | L9: 4 | M9: Hack n' Slash
A10: Arcadia Quest | B10: Orc Captain | C10: Minor Minion | D10: 1 | E10: 2 | F10: 4 | H10: 1 | I10: 2 | J10: 1 | K10: Melee | L10: 3 | M10: Hack n' Slash
A11: Arcadia Quest | B11: Orc Captain | C11: Minor Minion | D11: 2-3 | E11: 3 | F11: 5 | H11: 1 | I11: 2 | J11: 1 | K11: Melee | L11: 3 | M11: Hack n' Slash
A12: Arcadia Quest | B12: Orc Captain | C12: Minor Minion | D12: 4-5 | E12: 4 | F12: 6 | H12: 2 | I12: 2 | J12: 1 | K12: Melee | L12: 4 | M12: Hack n' Slash
A13: Arcadia Quest | B13: Orc Captain | C13: Minor Minion | D13: 6 | E13: 5 | F13: 7 | H13: 2 | I13: 2 | J13: 1 | K13: Melee | L13: 4 | M13: Hack n' Slash
A14: Arcadia Quest | B14: Spear Beastman | C14: Major Minion | D14: 1 | E14: 3 | F14: 5 | I14: 2 | J14: 1 | K14: Ranged | L14: 3 | M14: Javelin Throw | N14: Rolls +1 die if Close to any Monsters.
A15: Arcadia Quest | B15: Spear Beastman | C15: Major Minion | D15: 2-3 | E15: 4 | F15: 6 | I15: 2 | J15: 1 | K15: Ranged | L15: 3 | M15: Javelin Throw | N15: Rolls +1 die if Close to any Monsters.
A16: Arcadia Quest | B16: Spear Beastman | C16: Major Minion | D16: 4-5 | E16: 5 | F16: 7 | I16: 2 | J16: 1 | K16: Ranged | L16: 4 | M16: Javelin Throw | N16: Rolls +1 die if Close to any Monsters.
A17: Arcadia Quest | B17: Spear Beastman | C17: Major Minion | D17: 6 | E17: 7 | F17: 7 | I17: 2 | J17: 1 | K17: Ranged | L17: 4 | M17: Javelin Throw | N17: Rolls +1 die if Close to any Monsters.
A18: Arcadia Quest | B18: Hammer Beastman | C18: Major Minion | D18: 1 | E18: 3 | F18: 5 | I18: 2 | J18: 1 | K18: Melee | L18: 4 | M18: Hammer Time! | N18: If he deals a Wound, the target is Dazed.
A19: Arcadia Quest | B19: Hammer Beastman | C19: Major Minion | D19: 2-3 | E19: 4 | F19: 6 | I19: 2 | J19: 1 | K19: Melee | L19: 4 | M19: Hammer Time! | N19: If he deals a Wound, the target is Dazed.
A20: Arcadia Quest | B20: Hammer Beastman | C20: Major Minion | D20: 4-5 | E20: 5 | F20: 7 | I20: 2 | J20: 1 | K20: Melee | L20: 5 | M20: Hammer Time! | N20: If he deals a Wound, the target is Dazed.
A21: Arcadia Quest | B21: Hammer Beastman | C21: Major Minion | D21: 6 | E21: 7 | F21: 7 | I21: 2 | J21: 1 | K21: Melee | L21: 5 | M21: Hammer Time! | N21: If he deals a Wound, the target is Dazed.
A22: Arcadia Quest | B22: Minotaur | C22: Minor Villain | D22: 1 | E22: 5 | F22: 6 | G22: 1 | I22: 3 | J22: 2 | K22: Melee | L22: 4 | M22: Gouge | N22: Each Crit deals one additional hit.
A23: Arcadia Quest | B23: Minotaur | C23: Minor Villain | D23: 2-3 | E23: 6 | F23: 7 | G23: 1 | I23: 3 | J23: 2 | K23: Melee | L23: 4 | M23: Gouge | N23: Each Crit deals one additional hit.
A24: Arcadia Quest | B24: Minotaur | C24: Minor Villain | D24: 4-5 | E24: 7 | F24: 9 | G24: 2 | I24: 3 | J24: 2 | K24: Melee | L24: 5 | M24: Gouge | N24: Each Crit deals one additional hit.
A25: Arcadia Quest | B25: Minotaur | C25: Minor Villain | D25: 6 | E25: 8 | F25: 9 | G25: 2 | I25: 3 | J25: 2 | K25: Melee | L25: 5 | M25: Gouge | N25: Each Crit deals one additional hit.
A26: Arcadia Quest | B26: Troll | C26: Minor Villain | D26: 1 | E26: 4 | F26: 6 | G26: 2 | I26: 3 | J26: 2 | K26: Melee | L26: 4 | M26: Crush your Heads! | N26: Targets all Close Heroes.
A27: Arcadia Quest | B27: Troll | C27: Minor Villain | D27: 2-3 | E27: 5 | F27: 7 | G27: 2 | I27: 3 | J27: 2 | K27: Melee | L27: 4 | M27: Crush your Heads! | N27: Targets all Close Heroes.
A28: Arcadia Quest | B28: Troll | C28: Minor Villain | D28: 4-5 | E28: 6 | F28: 8 | G28: 3 | I28: 3 | J28: 2 | K28: Melee | L28: 5 | M28: Crush your Heads! | N28: Targets all Close Heroes.
A29: Arcadia Quest | B29: Troll | C29: Minor Villain | D29: 6 | E29: 8 | F29: 8 | G29: 3 | I29: 3 | J29: 2 | K29: Melee | L29: 5 | M29: Crush your Heads! | N29: Targets all Close Heroes.
A30: Arcadia Quest | B30: Sister of Pleasure | C30: Major Minion | D30: 1 | E30: 3 | F30: 5 | I30: 2 | J30: 1 | K30: Ranged | L30: 3 | M30: Siphon | N30: When attacking, each Crit heals 2 Wounds.
A31: Arcadia Quest | B31: Sister of Pleasure | C31: Major Minion | D31: 2-3 | E31: 4 | F31: 6 | I31: 2 | J31: 1 | K31: Ranged | L31: 4 | M31: Siphon | N31: When attacking, each Crit heals 2 Wounds.
A32: Arcadia Quest | B32: Sister of Pleasure | C32: Major Minion | D32: 4-5 | E32: 5 | F32: 7 | I32: 2 | J32: 1 | K32: Ranged | L32: 4 | M32: Siphon | N32: When attacking, each Crit heals 2 Wounds.
A33: Arcadia Quest | B33: Sister of Pleasure | C33: Major Minion | D33: 6 | E33: 7 | F33: 8 | I33: 2 | J33: 1 | K33: Ranged | L33: 5 | M33: Siphon | N33: When attacking, each Crit heals 2 Wounds.
A34: Arcadia Quest | B34: Sister of Pain | C34: Major Minion | D34: 1 | E34: 3 | F34: 5 | I34: 2 | J34: 1 | K34: Melee | L34: 3 | M34: Wail of Agony | N34: When attacking, each Crit exhausts one of the target's attack cards.
A35: Arcadia Quest | B35: Sister of Pain | C35: Major Minion | D35: 2-3 | E35: 4 | F35: 6 | I35: 2 | J35: 1 | K35: Melee | L35: 4 | M35: Wail of Agony | N35: When attacking, each Crit exhausts one of the target's attack cards.
A36: Arcadia Quest | B36: Sister of Pain | C36: Major Minion | D36: 4-5 | E36: 5 | F36: 7 | I36: 2 | J36: 1 | K36: Melee | L36: 4 | M36: Wail of Agony | N36: When attacking, each Crit exhausts one of the target's attack cards.
A37: Arcadia Quest | B37: Sister of Pain | C37: Major Minion | D37: 6 | E37: 7 | F37: 8 | I37: 2 | J37: 1 | K37: Melee | L37: 5 | M37: Wail of Agony | N37: When attacking, each Crit exhausts one of the target's attack cards.
A38: Arcadia Quest | B38: Lord Fang | C38: Major Villain | D38: 1 | E38: 5 | F38: 7 | I38: 3 | J38: 1 | K38: Ranged | L38: 4 | M38: Blood Bath | N38: May also target any number of Enemies Close to the target.
A39: Arcadia Quest | B39: Lord Fang | C39: Major Villain | D39: 2-3 | E39: 7 | F39: 8 | I39: 3 | J39: 1 | K39: Ranged | L39: 4 | M39: Blood Bath | N39: May also target any number of Enemies Close to the target.
A40: Arcadia Quest | B40: Lord Fang | C40: Major Villain | D40: 4-5 | E40: 8 | F40: 9 | G40: 2 | I40: 3 | J40: 1 | K40: Ranged | L40: 5 | M40: Blood Bath | N40: May also target any number of Enemies Close to the target.
...

Sheet Pets
A1: Set | B1: Name | C1: Sub-title | D1: Level | E1: Defense | F1: Health | G1: Ability Name | H1: Ability Description
A2: Dice Tower Promo | B2: Chuck | D2: 1 | E2: 0 | F2: 2 | G2: Dicey Pet | H2: May store up to 3 unused non-CRIT dice rolled by close owners (lost if Chuck dies). Close Owners may move these stored results to their rolls.
A3: Dice Tower Promo | B3: Chuck | D3: 2 | E3: 0 | F3: 3 | G3: Dicey Pet | H3: May store up to 3 unused non-CRIT dice rolled by close owners (lost if Chuck dies). Close Owners may move these stored results to their rolls.
A4: Dice Tower Promo | B4: Chuck | D4: 3 | E4: 0 | F4: 3 | G4: Dicey Pet | H4: May store up to 4 unused non-CRIT dice rolled by close owners (lost if Chuck dies). Close Owners may move these stored results to their rolls.
A5: Inferno KS | B5: Scrag | C5: Mascot Pet | D5: 1 | E5: 2 | F5: 3 | G5: I Hate Pets! | H5: When Scrag ends his Movement, he deals 1 Wound to 1 Close Enemy Pet.
A6: Inferno KS | B6: Scrag | C6: Mascot Pet | D6: 2 | E6: 2 | F6: 2 | G6: I Hate Pets! | H6: When Scrag ends his Movement, he deals 1 Wound to 2 Close Enemy Pets.
A7: Inferno KS | B7: Scrag | C7: Mascot Pet | D7: 3 | E7: 1 | F7: 2 | G7: I Hate Pets! | H7: When Scrag ends his Movement, he deals 2 Wounds to All Close Enemy Pets.
A8: Inferno KS | B8: Biru | C8: Mascot Pet | D8: 1 | E8: 1 | F8: 2 | G8: Biru! | H8: Entering and leaving Biru's Space costs no Movement Points to Owners.
A9: Inferno KS | B9: Biru | C9: Mascot Pet | D9: 2 | E9: 2 | F9: 3 | G9: Biru! | H9: Entering and leaving Biru's Space costs no Movement Points to Owners.
A10: Inferno KS | B10: Biru | C10: Mascot Pet | D10: 3 | E10: 3 | F10: 3 | G10: Biru! | H10: Entering and leaving Biru's Space costs no Movement Points to Owners.
A11: Inferno KS | B11: Bones | C11: Skelebone Pet | D11: 1 | E11: 0 | F11: 3 | G11: Deathbound | H11: Bones may take Wounds that Close Owners would have taken. Wounds cannot exceed his Life.
A12: Inferno KS | B12: Bones | C12: Skelebone Pet | D12: 2 | E12: 1 | F12: 4 | G12: Deathbound | H12: Bones may take Wounds that Close Owners would have taken. Wounds cannot exceed his Life.
A13: Inferno KS | B13: Bones | C13: Skelebone Pet | D13: 3 | E13: 1 | F13: 5 | G13: Deathbound | H13: Bones may take Wounds that Close Owners would have taken. Wounds cannot exceed his Life.
A14: Inferno KS | B14: Gadget | C14: Critter Pet | D14: 1 | E14: 2 | F14: 2 | G14: Hold the Door! | H14: Close Enemy Heroes can't use Portals or open Doors.
A15: Inferno KS | B15: Gadget | C15: Critter Pet | D15: 2 | E15: 3 | F15: 3 | G15: Hold the Door! | H15: Close Enemy Heroes can't use Portals or open Doors.
A16: Inferno KS | B16: Gadget | C16: Critter Pet | D16: 3 | E16: 3 | F16: 4 | G16: Hold the Door! | H16: Close Enemy Heroes can't use Portals or open Doors.
... A79: Pets KS Bonus | B79: Cerby | C79: Helldog Pet | D79: 3 | E79: 1 | F79: 3 | G79: Sic 'em! | H79: When an Owner attacks an Enemy in Cerby's Space, the attack may target 3 additional Enemies Close to it.

Sheet Mounts
